Ignoring exception in command None:
discord.ext.commands.errors.CommandNotFound: Command "challenge" is not found
Ignoring exception in command chess new challenge:
Traceback (most recent call last):
  File "/usr/local/lib/python3.6/dist-packages/discord/ext/commands/bot.py", line 814, in invoke
    await ctx.command.invoke(ctx)
  File "/usr/local/lib/python3.6/dist-packages/discord/ext/commands/core.py", line 1119, in invoke
    await ctx.invoked_subcommand.invoke(ctx)
  File "/usr/local/lib/python3.6/dist-packages/discord/ext/commands/core.py", line 1119, in invoke
    await ctx.invoked_subcommand.invoke(ctx)
  File "/usr/local/lib/python3.6/dist-packages/discord/ext/commands/core.py", line 675, in invoke
    await self.prepare(ctx)
  File "/usr/local/lib/python3.6/dist-packages/discord/ext/commands/core.py", line 640, in prepare
    await self._parse_arguments(ctx)
  File "/usr/local/lib/python3.6/dist-packages/discord/ext/commands/core.py", line 561, in _parse_arguments
    transformed = await self.transform(ctx, param)
  File "/usr/local/lib/python3.6/dist-packages/discord/ext/commands/core.py", line 417, in transform
    raise MissingRequiredArgument(param)
discord.ext.commands.errors.MissingRequiredArgument: white is a required argument that is missing.
Ignoring exception in command sauce:
Traceback (most recent call last):
  File "/usr/local/lib/python3.6/dist-packages/discord/ext/commands/core.py", line 64, in wrapped
    ret = await coro(*args, **kwargs)
  File "/home/spamsuckersunited/FinBot/main.py", line 1069, in sauce
    url = file[0]['proxy_url']
TypeError: 'Attachment' object is not subscriptable

The above exception was the direct cause of the following exception:

Traceback (most recent call last):
  File "/usr/local/lib/python3.6/dist-packages/discord/ext/commands/bot.py", line 814, in invoke
    await ctx.command.invoke(ctx)
  File "/usr/local/lib/python3.6/dist-packages/discord/ext/commands/core.py", line 682, in invoke
    await injected(*ctx.args, **ctx.kwargs)
  File "/usr/local/lib/python3.6/dist-packages/discord/ext/commands/core.py", line 73, in wrapped
    raise CommandInvokeError(exc) from exc
discord.ext.commands.errors.CommandInvokeError: Command raised an exception: TypeError: 'Attachment' object is not subscriptable
Ignoring exception in command sauce:
Traceback (most recent call last):
  File "/usr/local/lib/python3.6/dist-packages/discord/ext/commands/core.py", line 64, in wrapped
    ret = await coro(*args, **kwargs)
  File "/home/spamsuckersunited/FinBot/main.py", line 1069, in sauce
    url = file[0]['proxy_url']
TypeError: 'Attachment' object is not subscriptable

The above exception was the direct cause of the following exception:

Traceback (most recent call last):
  File "/usr/local/lib/python3.6/dist-packages/discord/ext/commands/bot.py", line 814, in invoke
    await ctx.command.invoke(ctx)
  File "/usr/local/lib/python3.6/dist-packages/discord/ext/commands/core.py", line 682, in invoke
    await injected(*ctx.args, **ctx.kwargs)
  File "/usr/local/lib/python3.6/dist-packages/discord/ext/commands/core.py", line 73, in wrapped
    raise CommandInvokeError(exc) from exc
discord.ext.commands.errors.CommandInvokeError: Command raised an exception: TypeError: 'Attachment' object is not subscriptable
Ignoring exception in command source:
Traceback (most recent call last):
  File "/usr/local/lib/python3.6/dist-packages/discord/ext/commands/core.py", line 64, in wrapped
    ret = await coro(*args, **kwargs)
  File "/home/spamsuckersunited/FinBot/main.py", line 1038, in source
    source = str(inspect.getsource(client.get_command(' '.join(command)).callback))
AttributeError: 'NoneType' object has no attribute 'callback'

The above exception was the direct cause of the following exception:

Traceback (most recent call last):
  File "/usr/local/lib/python3.6/dist-packages/discord/ext/commands/bot.py", line 814, in invoke
    await ctx.command.invoke(ctx)
  File "/usr/local/lib/python3.6/dist-packages/discord/ext/commands/core.py", line 682, in invoke
    await injected(*ctx.args, **ctx.kwargs)
  File "/usr/local/lib/python3.6/dist-packages/discord/ext/commands/core.py", line 73, in wrapped
    raise CommandInvokeError(exc) from exc
discord.ext.commands.errors.CommandInvokeError: Command raised an exception: AttributeError: 'NoneType' object has no attribute 'callback'
Ignoring exception in command chess new challenge:
Traceback (most recent call last):
  File "/usr/local/lib/python3.6/dist-packages/discord/ext/commands/core.py", line 64, in wrapped
    ret = await coro(*args, **kwargs)
  File "/home/spamsuckersunited/FinBot/main.py", line 754, in challenge
    if chess_game.result() == '1-0' or black_ended:
UnboundLocalError: local variable 'black_ended' referenced before assignment

The above exception was the direct cause of the following exception:

Traceback (most recent call last):
  File "/usr/local/lib/python3.6/dist-packages/discord/ext/commands/bot.py", line 814, in invoke
    await ctx.command.invoke(ctx)
  File "/usr/local/lib/python3.6/dist-packages/discord/ext/commands/core.py", line 1119, in invoke
    await ctx.invoked_subcommand.invoke(ctx)
  File "/usr/local/lib/python3.6/dist-packages/discord/ext/commands/core.py", line 1119, in invoke
    await ctx.invoked_subcommand.invoke(ctx)
  File "/usr/local/lib/python3.6/dist-packages/discord/ext/commands/core.py", line 682, in invoke
    await injected(*ctx.args, **ctx.kwargs)
  File "/usr/local/lib/python3.6/dist-packages/discord/ext/commands/core.py", line 73, in wrapped
    raise CommandInvokeError(exc) from exc
discord.ext.commands.errors.CommandInvokeError: Command raised an exception: UnboundLocalError: local variable 'black_ended' referenced before assignment
Ignoring exception in command None:
discord.ext.commands.errors.CommandNotFound: Command "end" is not found
Ignoring exception in command None:
discord.ext.commands.errors.CommandNotFound: Command "Clever" is not found
Ignoring exception in command None:
discord.ext.commands.errors.CommandNotFound: Command "Clever" is not found
Ignoring exception in command None:
discord.ext.commands.errors.CommandNotFound: Command "Clever" is not found
Ignoring exception in command clever:
Traceback (most recent call last):
  File "/usr/local/lib/python3.6/dist-packages/discord/ext/commands/bot.py", line 814, in invoke
    await ctx.command.invoke(ctx)
  File "/usr/local/lib/python3.6/dist-packages/discord/ext/commands/core.py", line 675, in invoke
    await self.prepare(ctx)
  File "/usr/local/lib/python3.6/dist-packages/discord/ext/commands/core.py", line 640, in prepare
    await self._parse_arguments(ctx)
  File "/usr/local/lib/python3.6/dist-packages/discord/ext/commands/core.py", line 575, in _parse_arguments
    transformed = await self.transform(ctx, param)
  File "/usr/local/lib/python3.6/dist-packages/discord/ext/commands/core.py", line 424, in transform
    argument = quoted_word(view)
  File "/usr/local/lib/python3.6/dist-packages/discord/ext/commands/view.py", line 180, in quoted_word
    raise BadArgument('Unexpected quote mark in non-quoted string')
discord.ext.commands.errors.BadArgument: Unexpected quote mark in non-quoted string
Ignoring exception in command None:
discord.ext.commands.errors.CommandNotFound: Command "Clever" is not found
Ignoring exception in command None:
discord.ext.commands.errors.CommandNotFound: Command "Clever" is not found
Ignoring exception in command None:
discord.ext.commands.errors.CommandNotFound: Command "Clever" is not found
Ignoring exception in command None:
discord.ext.commands.errors.CommandNotFound: Command "8clever" is not found
Ignoring exception in command None:
discord.ext.commands.errors.CommandNotFound: Command "8clever" is not found
Ignoring exception in command clever:
Traceback (most recent call last):
  File "/usr/local/lib/python3.6/dist-packages/discord/ext/commands/bot.py", line 814, in invoke
    await ctx.command.invoke(ctx)
  File "/usr/local/lib/python3.6/dist-packages/discord/ext/commands/core.py", line 675, in invoke
    await self.prepare(ctx)
  File "/usr/local/lib/python3.6/dist-packages/discord/ext/commands/core.py", line 640, in prepare
    await self._parse_arguments(ctx)
  File "/usr/local/lib/python3.6/dist-packages/discord/ext/commands/core.py", line 575, in _parse_arguments
    transformed = await self.transform(ctx, param)
  File "/usr/local/lib/python3.6/dist-packages/discord/ext/commands/core.py", line 424, in transform
    argument = quoted_word(view)
  File "/usr/local/lib/python3.6/dist-packages/discord/ext/commands/view.py", line 180, in quoted_word
    raise BadArgument('Unexpected quote mark in non-quoted string')
discord.ext.commands.errors.BadArgument: Unexpected quote mark in non-quoted string
Ignoring exception in command clever:
Traceback (most recent call last):
  File "/usr/local/lib/python3.6/dist-packages/discord/ext/commands/bot.py", line 814, in invoke
    await ctx.command.invoke(ctx)
  File "/usr/local/lib/python3.6/dist-packages/discord/ext/commands/core.py", line 675, in invoke
    await self.prepare(ctx)
  File "/usr/local/lib/python3.6/dist-packages/discord/ext/commands/core.py", line 640, in prepare
    await self._parse_arguments(ctx)
  File "/usr/local/lib/python3.6/dist-packages/discord/ext/commands/core.py", line 575, in _parse_arguments
    transformed = await self.transform(ctx, param)
  File "/usr/local/lib/python3.6/dist-packages/discord/ext/commands/core.py", line 424, in transform
    argument = quoted_word(view)
  File "/usr/local/lib/python3.6/dist-packages/discord/ext/commands/view.py", line 180, in quoted_word
    raise BadArgument('Unexpected quote mark in non-quoted string')
discord.ext.commands.errors.BadArgument: Unexpected quote mark in non-quoted string
Ignoring exception in command clever:
Traceback (most recent call last):
  File "/usr/local/lib/python3.6/dist-packages/discord/ext/commands/bot.py", line 814, in invoke
    await ctx.command.invoke(ctx)
  File "/usr/local/lib/python3.6/dist-packages/discord/ext/commands/core.py", line 675, in invoke
    await self.prepare(ctx)
  File "/usr/local/lib/python3.6/dist-packages/discord/ext/commands/core.py", line 640, in prepare
    await self._parse_arguments(ctx)
  File "/usr/local/lib/python3.6/dist-packages/discord/ext/commands/core.py", line 575, in _parse_arguments
    transformed = await self.transform(ctx, param)
  File "/usr/local/lib/python3.6/dist-packages/discord/ext/commands/core.py", line 424, in transform
    argument = quoted_word(view)
  File "/usr/local/lib/python3.6/dist-packages/discord/ext/commands/view.py", line 180, in quoted_word
    raise BadArgument('Unexpected quote mark in non-quoted string')
discord.ext.commands.errors.BadArgument: Unexpected quote mark in non-quoted string
Ignoring exception in command code run:
Traceback (most recent call last):
  File "/usr/local/lib/python3.6/dist-packages/discord/ext/commands/core.py", line 64, in wrapped
    ret = await coro(*args, **kwargs)
  File "/home/spamsuckersunited/FinBot/main.py", line 1249, in run
    raise e
  File "/home/spamsuckersunited/FinBot/main.py", line 1243, in run
    _, output = split_data
ValueError: not enough values to unpack (expected 2, got 1)

The above exception was the direct cause of the following exception:

Traceback (most recent call last):
  File "/usr/local/lib/python3.6/dist-packages/discord/ext/commands/bot.py", line 814, in invoke
    await ctx.command.invoke(ctx)
  File "/usr/local/lib/python3.6/dist-packages/discord/ext/commands/core.py", line 1119, in invoke
    await ctx.invoked_subcommand.invoke(ctx)
  File "/usr/local/lib/python3.6/dist-packages/discord/ext/commands/core.py", line 682, in invoke
    await injected(*ctx.args, **ctx.kwargs)
  File "/usr/local/lib/python3.6/dist-packages/discord/ext/commands/core.py", line 73, in wrapped
    raise CommandInvokeError(exc) from exc
discord.ext.commands.errors.CommandInvokeError: Command raised an exception: ValueError: not enough values to unpack (expected 2, got 1)
Ignoring exception in command code run:
Traceback (most recent call last):
  File "/usr/local/lib/python3.6/dist-packages/discord/ext/commands/bot.py", line 814, in invoke
    await ctx.command.invoke(ctx)
  File "/usr/local/lib/python3.6/dist-packages/discord/ext/commands/core.py", line 1119, in invoke
    await ctx.invoked_subcommand.invoke(ctx)
  File "/usr/local/lib/python3.6/dist-packages/discord/ext/commands/core.py", line 675, in invoke
    await self.prepare(ctx)
  File "/usr/local/lib/python3.6/dist-packages/discord/ext/commands/core.py", line 640, in prepare
    await self._parse_arguments(ctx)
  File "/usr/local/lib/python3.6/dist-packages/discord/ext/commands/core.py", line 561, in _parse_arguments
    transformed = await self.transform(ctx, param)
  File "/usr/local/lib/python3.6/dist-packages/discord/ext/commands/core.py", line 417, in transform
    raise MissingRequiredArgument(param)
discord.ext.commands.errors.MissingRequiredArgument: language is a required argument that is missing.
Ignoring exception in command code run:
Traceback (most recent call last):
  File "/usr/local/lib/python3.6/dist-packages/discord/ext/commands/core.py", line 64, in wrapped
    ret = await coro(*args, **kwargs)
  File "/home/spamsuckersunited/FinBot/main.py", line 1249, in run
    raise e
  File "/home/spamsuckersunited/FinBot/main.py", line 1243, in run
    _, output = split_data
ValueError: not enough values to unpack (expected 2, got 1)

The above exception was the direct cause of the following exception:

Traceback (most recent call last):
  File "/usr/local/lib/python3.6/dist-packages/discord/ext/commands/bot.py", line 814, in invoke
    await ctx.command.invoke(ctx)
  File "/usr/local/lib/python3.6/dist-packages/discord/ext/commands/core.py", line 1119, in invoke
    await ctx.invoked_subcommand.invoke(ctx)
  File "/usr/local/lib/python3.6/dist-packages/discord/ext/commands/core.py", line 682, in invoke
    await injected(*ctx.args, **ctx.kwargs)
  File "/usr/local/lib/python3.6/dist-packages/discord/ext/commands/core.py", line 73, in wrapped
    raise CommandInvokeError(exc) from exc
discord.ext.commands.errors.CommandInvokeError: Command raised an exception: ValueError: not enough values to unpack (expected 2, got 1)
Ignoring exception in command code run:
Traceback (most recent call last):
  File "/usr/local/lib/python3.6/dist-packages/discord/ext/commands/core.py", line 64, in wrapped
    ret = await coro(*args, **kwargs)
  File "/home/spamsuckersunited/FinBot/main.py", line 1249, in run
    raise e
  File "/home/spamsuckersunited/FinBot/main.py", line 1243, in run
    _, output = split_data
ValueError: not enough values to unpack (expected 2, got 1)

The above exception was the direct cause of the following exception:

Traceback (most recent call last):
  File "/usr/local/lib/python3.6/dist-packages/discord/ext/commands/bot.py", line 814, in invoke
    await ctx.command.invoke(ctx)
  File "/usr/local/lib/python3.6/dist-packages/discord/ext/commands/core.py", line 1119, in invoke
    await ctx.invoked_subcommand.invoke(ctx)
  File "/usr/local/lib/python3.6/dist-packages/discord/ext/commands/core.py", line 682, in invoke
    await injected(*ctx.args, **ctx.kwargs)
  File "/usr/local/lib/python3.6/dist-packages/discord/ext/commands/core.py", line 73, in wrapped
    raise CommandInvokeError(exc) from exc
discord.ext.commands.errors.CommandInvokeError: Command raised an exception: ValueError: not enough values to unpack (expected 2, got 1)
Ignoring exception in command code run:
Traceback (most recent call last):
  File "/usr/local/lib/python3.6/dist-packages/discord/ext/commands/core.py", line 64, in wrapped
    ret = await coro(*args, **kwargs)
  File "/home/spamsuckersunited/FinBot/main.py", line 1249, in run
    raise e
  File "/home/spamsuckersunited/FinBot/main.py", line 1243, in run
    _, output = split_data
ValueError: not enough values to unpack (expected 2, got 1)

The above exception was the direct cause of the following exception:

Traceback (most recent call last):
  File "/usr/local/lib/python3.6/dist-packages/discord/ext/commands/bot.py", line 814, in invoke
    await ctx.command.invoke(ctx)
  File "/usr/local/lib/python3.6/dist-packages/discord/ext/commands/core.py", line 1119, in invoke
    await ctx.invoked_subcommand.invoke(ctx)
  File "/usr/local/lib/python3.6/dist-packages/discord/ext/commands/core.py", line 682, in invoke
    await injected(*ctx.args, **ctx.kwargs)
  File "/usr/local/lib/python3.6/dist-packages/discord/ext/commands/core.py", line 73, in wrapped
    raise CommandInvokeError(exc) from exc
discord.ext.commands.errors.CommandInvokeError: Command raised an exception: ValueError: not enough values to unpack (expected 2, got 1)
Ignoring exception in command code run:
Traceback (most recent call last):
  File "/usr/local/lib/python3.6/dist-packages/discord/ext/commands/core.py", line 64, in wrapped
    ret = await coro(*args, **kwargs)
  File "/home/spamsuckersunited/FinBot/main.py", line 1249, in run
    raise e
  File "/home/spamsuckersunited/FinBot/main.py", line 1243, in run
    _, output = split_data
ValueError: not enough values to unpack (expected 2, got 1)

The above exception was the direct cause of the following exception:

Traceback (most recent call last):
  File "/usr/local/lib/python3.6/dist-packages/discord/ext/commands/bot.py", line 814, in invoke
    await ctx.command.invoke(ctx)
  File "/usr/local/lib/python3.6/dist-packages/discord/ext/commands/core.py", line 1119, in invoke
    await ctx.invoked_subcommand.invoke(ctx)
  File "/usr/local/lib/python3.6/dist-packages/discord/ext/commands/core.py", line 682, in invoke
    await injected(*ctx.args, **ctx.kwargs)
  File "/usr/local/lib/python3.6/dist-packages/discord/ext/commands/core.py", line 73, in wrapped
    raise CommandInvokeError(exc) from exc
discord.ext.commands.errors.CommandInvokeError: Command raised an exception: ValueError: not enough values to unpack (expected 2, got 1)
Starting...
Logged in as Fin Bot
Invite URL:
https://discordapp.com/oauth2/authorize?client_id=464543446187769867&scope=bot&permissions=2146958847
Unclosed client session
client_session: <aiohttp.client.ClientSession object at 0x7f518a1998d0>
Unclosed connector
connections: ['[(<aiohttp.client_proto.ResponseHandler object at 0x7f517850dee8>, 64399.851700757)]']
connector: <aiohttp.connector.TCPConnector object at 0x7f518a199908>
Task was destroyed but it is pending!
task: <Task pending coro=<DiscordWebSocket.close_connection() running at /usr/local/lib/python3.6/dist-packages/discord/gateway.py:539> wait_for=<Future pending cb=[<TaskWakeupMethWrapper object at 0x7f51783c9768>()]> cb=[shield.<locals>._done_callback() at /usr/lib/python3.6/asyncio/tasks.py:688]>
Task was destroyed but it is pending!
task: <Task pending coro=<BotBase.close() running at /usr/local/lib/python3.6/dist-packages/discord/ext/commands/bot.py:210> wait_for=<Future pending cb=[<TaskWakeupMethWrapper object at 0x7f51783c9648>()]> cb=[Client._do_cleanup.<locals>.when_future_is_done() at /usr/local/lib/python3.6/dist-packages/discord/client.py:498]>
